Workbook

Sheet Proc & Work Type details
B2: Process​ | D2: Description​ | E2: Activities to Transition​
B4: Pre Placement​ | C4: Client Discovery​ | D4: Activities to understand the client’s business, risk profile, coverage needs, and objectives to inform program design and placement strategy​ | E4: Data Retrieval - Loss Run Management (Carrier Websites)
E5: Data Loading / Analytics Support - SOV / Exposure Summary (Excel)
E6: Data Loading / Analytics Support - SOV / Exposure Summary (Excel)
E7: Data Loading / Analytics Support - Summary of Insurance (Word / Epic)
E8: Data Loading / Analytics Support - Summary of Insurance (Excel)
C10: Renewal Planning​ | D10: Planning and coordination of renewal strategy, timelines, data requirements, and market approach to ensure policy renewal​ | E10: Policy Validation & Endorsement Reconciliation (Epic)
C12: Submission Creation​ | D12: Preparation of underwriting submissions, including exposure data, loss history, and supporting documentation, for delivery to insurance markets​ | E12: Policy Setup / Creation / Submission in Epic
E14: Pre-filling supplemental applications with prior / existing client or app data​
B16: Placement​ | C16: Program Brokering​ | D16: Marketing of the client’s insurance program to carriers, negotiation of terms and pricing, and coordination of carrier responses to secure optimal coverage​ | E16: Online Quoting
C18: Quote Review​ | D18: Comparison of carrier quotes including key policy details (e.g., changes from expiring, form inclusions, edition dates), to identify suitable options for client consideration​ | E18: Coverage Comparison – Expiring vs Renewal
C20: Quote Presentation​ | D20: Compilation and presentation of carrier quotes, including coverage comparisons, pricing, and key terms, to support client decision-making​ | E20: Proposal Preparation
C22: Bind Authorization & Review​ | D22: Confirmation of client binding instructions, review of final terms and conditions, and authorization to bind coverage with selected carrier(s)​ | E22: Epic Client Setup
C24: Premium Financing​ | D24: Coordination of premium financing options as requested by the client​ | E24: **Premium finance agreements (PFAs)​
C26: Invoicing​ | D26: Preparation and issuance of client invoices reflecting premiums, fees, taxes, and payment terms following policy binding​
E29: Invoice Creation
E30: Surplus Lines Compliance Preparation
B36: Post Placement​ | C36: Evidence of Coverage​ | D36: Issuance and management of certificates and other evidence of insurance documents to verify coverage for clients and third parties​ | E36: Mid-term Certificate of Insurance
E38: Renewal Certificates of Insurance
E40: Evidence of Property
E42: Auto ID Cards
E43: Renewal Auto ID Cards
C44: Policy Administration​ | D44: Ongoing administration of active policies, including documentation management, system updates, and coordination with carriers and service teams​ | E44: Conduct Policy Review / Check
E46: Download Policy Documents & Attach to Epic
E50: Check Premium Audit & Complete Audit Comparison
E52: Audit Review
C54: Endorsements​ | D54: Processing of policy changes, including coverage modifications, limits, locations, or exposures, and issuance of updated documentation and billing as applicable​ | E54: Collect & Confirm Change Request Information
E56: Follow Up for Endorsement
E58: Check Endorsement Against Change Request
E60: Process Cancellations
B62: Claims​ | C62: Claim Management / Oversight​ | D62: Coordination and oversight of claim activity​ | E62: Claim creation​ (Rush)
E63: Claims Data Entry (Std)
E64: Claims Data Entry (Doc Update)
E66: Claims Without Activity Alerts
E68: Activities Without Claims Alerts
C70: Claims Analytics​ | D70: Analysis and reporting of claims data to identify trends, support renewal and placement strategy, and provide insights to clients and service teams​ | E70: Request Loss Runs from Carrier
E72: Formatting / Converting Loss Run PDFs
C74: Claim Creation Guide​ | D74: Development and maintenance of client-specific guidance outlining claim reporting procedures, carrier contacts, and required information for claim submission​ | E74: Update Client Guides for Claim Creation

Sheet Team Structure
B1: SBU - Select Business Unit | E1: AMS - Account Management Services | H1: CSD - Client Service Delivery
A2: Sr No | B2: Name | C2: ARL | D2: Process / Work Type | E2: Name | F2: ARL | G2: Process / Work Type | H2: Name | I2: ARL | J2: Process / Work Type
A3: 1 | B3: Mohamed Bilal Nazeer Ahamed | C3: 5 | E3: Farukali Mujawar | F3: 5 | H3: Ritesh Shetty | I3: 5
A4: 2
A5: 3
A6: 4
A7: 5
A8: 6
A9: 7
A10: 8
A11: 9
A12: 10
A13: 11
A14: 12
A15: 13
... A50: 48

Sheet Curr
A1: RAG Legend | C1: 0-6 mnths | E1: 6 - 18 mnths | G1: 18+ mnths
A3: Sr | B3: Employee Name | C3: ARL | D3: Exp Info | G3: Worktypes mirroring NFP Definitions | V3: Loss runs | W3: Other Skills & Exposure | AC3: Sys & App Exp | AG3: Desigtions / Certifications
G4: Pre - Placement | J4: Placement | P4: Post - Placement | S4: Claims | W4: MIS | X4: Auto | Y4: App / Sys Migration | Z4: Training / OJ Support | AA4: Proc Exc (YB / GB / BB / MBB) | AB4: Onshore Trans ( remote) | AC4: EPIC | AD4: AMS 360 | AE4: CSR24 | AF4: IMAGERIGHT | AG4: Institutes | AH4: Cert CII
D5: Tot (yrs) | E5: P&C (yrs) | F5: Geo Exp | G5: Client Discovery | H5: Renewal Planning | I5: Subm Creation | J5: Program Brokering | K5: Quote Review | L5: Quote presentation | M5: Bind Auth & Review​ | N5: Premium Financing | O5: Inv | P5: Evidence of Coverage | Q5: Pol Admin | R5: Endmnt | S5: Claims Mgmt & Oversight | T5: Claims Analytics | U5: Claims Creation Guide
A6: 1 | B6: JaYesh Shetty | C6: 7 | D6: 8-10 | E6: 5-7 | F6: USA;UK | G6: 18+ mnths | H6: 6 - 18 mnths | P6: 6 - 18 mnths | R6: 6 - 18 mnths | S6: 6 - 18 mnths | Z6: Yes
A7: 2 | B7: Santosh Chauhan | C7: 7 | D7: 10+ | E7: 8-10 | F7: USA | H7: 18+ mnths | O7: 18+ mnths | P7: 18+ mnths | Q7: 18+ mnths | Y7: Yes | AC7: Yes
A8: 3 | B8: Vikram Anand | C8: 7 | D8: 10+ | E8: 7-8 | F8: USA;UK | H8: 6 - 18 mnths | V8: Yes | Y8: Yes | Z8: Yes | AB8: Yes
A9: 4 | B9: Harish Anand | C9: 8 | D9: 3-5 | E9: 3-5 | F9: UK | S9: 18+ mnths
A10: 5 | B10: Pradeep Kumar L | C10: 8 | D10: 3-5 | E10: 1.5 - 3 | F10: AUS | T10: 6 - 18 mnths
A11: 6 | B11: Shelina Jena | C11: 7 | D11: 5-7 | E11: 0.5 - 1.5 | F11: USA | U11: 18+ mnths | V11: Yes
A12: 7 | B12: Veeranagaraj Hiremath | C12: 7 | D12: 5-7 | E12: 3-5 | F12: USA;Canada; | H12: 18+ mnths | K12: 18+ mnths | L12: 18+ mnths | O12: 18+ mnths | Q12: 18+ mnths | V12: Yes | Z12: Yes
A13: 8 | B13: Amrutha Arali | C13: 7 | D13: 5-7 | E13: 3-5 | F13: USA | H13: 18+ mnths | R13: 18+ mnths | AC13: Yes | AE13: Yes
A14: 9 | B14: M Dhanashekar | C14: 8 | D14: 3-5 | E14: 0.5 - 1.5 | F14: USA | H14: 6 - 18 mnths | S14: 18+ mnths | V14: Yes
A15: 10 | B15: Apoorva H A | C15: 8 | D15: 3-5 | E15: 3-5 | F15: USA | H15: 18+ mnths | O15: 6 - 18 mnths | V15: Yes | W15: Yes | Z15: Yes | AA15: Yes | AB15: Yes | AC15: Yes
A16: 11 | B16: Naresh Moguram | C16: 7 | D16: 10+ | E16: 7-8 | F16: USA | H16: 18+ mnths | R16: 18+ mnths | V16: Yes | Z16: Yes
A17: 12 | B17: Vikram Prakash Bhat | C17: 8 | D17: 7-8 | E17: 7-8 | F17: USA | H17: 18+ mnths | V17: Yes | W17: Yes | Z17: Yes | AC17: Yes | AF17: Yes
A18: 13 | B18: Nidhi Kumari | C18: 8 | D18: 5-7 | E18: 5-7 | F18: UK | H18: 18+ mnths | O18: 18+ mnths | Q18: 18+ mnths | Z18: Yes
A19: 14 | B19: Prince Peter | C19: 7 | D19: 10+ | E19: 7-8 | F19: UK & AUS | H19: 18+ mnths | R19: 18+ mnths | Z19: Yes
A20: 15 | B20: Joyline Viola Rebello | C20: 8 | D20: 3-5 | E20: 3-5 | F20: APAC & UK | H20: 18+ mnths | T20: 18+ mnths | V20: Yes | Z20: Yes
A21: 16 | B21: Abishek V | C21: 8 | D21: 7-8 | E21: 3-5 | F21: USA | H21: 18+ mnths | P21: 18+ mnths | S21: 6 - 18 mnths | V21: Yes | Z21: Yes
A22: 17 | B22: Lakshmipathy Chalicheemala | C22: 8 | D22: 1.5 - 3 | E22: 0.5 - 1.5 | F22: USA | L22: 6 - 18 mnths | R22: 6 - 18 mnths | V22: Yes | Z22: Yes | AF22: Yes
A23: 18 | B23: Geetanjali G | C23: 8 | D23: 5-7 | E23: 5-7 | F23: UK | H23: 18+ mnths | O23: 18+ mnths | Q23: 18+ mnths | W23: Yes | Z23: Yes | AA23: Yes
A24: 19 | B24: Pooja S | C24: 8 | D24: 5-7 | E24: 3-5 | F24: USA | H24: 18+ mnths | R24: 18+ mnths | Z24: Yes | AD24: Yes | AF24: Yes
A25: 20 | B25: Mohan V Kumar | C25: 8 | D25: 3-5 | E25: 3-5 | F25: USA | P25: 18+ mnths | V25: Yes | Z25: Yes | AC25: Yes | AE25: Yes | AF25: Yes
A26: 21 | B26: Natri Aakash | C26: 8 | D26: 3-5 | E26: 3-5 | F26: USA | H26: 18+ mnths | I26: 18+ mnths | K26: 18+ mnths | M26: 18+ mnths | S26: 18+ mnths | W26: Yes | X26: Yes | Z26: Yes
A27: 22 | B27: Suma P | C27: 8 | D27: 3-5 | E27: 3-5 | F27: USA | H27: 18+ mnths | I27: 6 - 18 mnths | Q27: 6 - 18 mnths | V27: Yes | Z27: Yes | AC27: Yes | AD27: Yes | AF27: Yes
A28: 23 | B28: Thirumala Reddy S | C28: 8 | D28: 3-5 | E28: 3-5 | F28: USA | P28: 18+ mnths | AC28: Yes | AE28: Yes
A29: 24 | B29: Zaiba Sulthana | C29: 8 | D29: 3-5 | E29: 1.5 - 3 | F29: USA | H29: 18+ mnths | Z29: Yes | AC29: Yes
A30: 25 | B30: Chetankumar Honakeri | C30: 7 | D30: 10+ | E30: 7-8 | F30: USA | P30: 18+ mnths | V30: Yes | Z30: Yes | AC30: Yes | AD30: Yes | AE30: Yes | AF30: Yes
A31: 26 | B31: Sanjeev Krishna V | C31: 8 | D31: 3-5 | E31: 3-5 | F31: USA | H31: 18+ mnths | K31: 18+ mnths | L31: 18+ mnths | M31: 18+ mnths | O31: 6 - 18 mnths | R31: 6 - 18 mnths | S31: 18+ mnths | Z31: Yes | AF31: Yes
A32: 27 | B32: Rohith R | C32: 8 | D32: 3-5 | E32: 1.5 - 3 | F32: USA | H32: 6 - 18 mnths | O32: 6 - 18 mnths | V32: Yes | Z32: Yes
A33: 28 | B33: Sajith C P | C33: 8 | D33: 1.5 - 3 | E33: 0.5 - 1.5 | F33: USA | H33: 18+ mnths | AC33: Yes
A34: 29 | B34: Sachin AK | C34: 8 | D34: 1.5 - 3 | E34: 1.5 - 3 | F34: USA | H34: 18+ mnths | L34: 6 - 18 mnths | V34: Yes | Z34: Yes | AC34: Yes | AF34: Yes
A35: 30 | B35: Santhosh HS | C35: 8 | D35: 10+ | E35: 5-7 | F35: USA | H35: 18+ mnths | O35: 18+ mnths | R35: 18+ mnths | V35: Yes | Z35: Yes | AF35: Yes
A36: 31 | B36: Meagan Lewis | C36: 8 | D36: 7-8 | E36: 1.5 - 3 | F36: USA;UK | H36: 18+ mnths | Z36: Yes | AC36: Yes
A37: 32 | B37: Sandhya MS | C37: 8 | D37: 7-8 | E37: 7-8 | F37: USA | H37: 18+ mnths | I37: 18+ mnths | K37: 18+ mnths | L37: 18+ mnths | M37: 18+ mnths | R37: 18+ mnths | V37: Yes | Z37: Yes | AC37: Yes | AD37: Yes | AF37: Yes
A38: 33 | B38: Arun M U | C38: 7 | D38: 5-7 | E38: 3-5 | F38: USA | H38: 18+ mnths | T38: 18+ mnths | Z38: Yes | AB38: Yes
A39: 34 | B39: Chethan HS | C39: 8 | D39: 3-5 | E39: 3-5 | F39: USA | H39: 18+ mnths | R39: 18+ mnths | S39: 18+ mnths | V39: Yes | W39: Yes | Z39: Yes | AB39: Yes | AC39: Yes | AD39: Yes | AF39: Yes
A40: 35 | B40: Harshitha K | C40: 8 | D40: 3-5 | E40: 0.5 - 1.5 | F40: UK | H40: 18+ mnths | M40: 18+ mnths | O40: 18+ mnths | P40: 18+ mnths | S40: 18+ mnths | T40: 18+ mnths | U40: 18+ mnths | V40: Yes | Z40: Yes | AB40: Yes
A41: 36 | B41: Kiran Doddagoudar | C41: 8 | D41: 1.5 - 3 | E41: 1.5 - 3 | F41: USA | P41: 18+ mnths | R41: 18+ mnths | S41: 18+ mnths | AC41: Yes
...

Sheet Tables
J1: Yes | K1: Yes | L1: Yes | M1: Yes | N1: Yes | O1: Yes | P1: Yes | Q1: Yes | R1: Yes | S1: Yes
B2: ARL Count | E2: Overall Experience | H2: P&C Experience | K2: Other Skills & Exposure | O2: Process Experience
B3: ARL | C3: No of colleagues | E3: Overall Exp in years | F3: No of colleagues | H3: Exp in Years | I3: No of Colleagues | K3: Skill | L3: No of Colleagues | O3: Process | P3: 0-6 mnths | Q3: 6 - 18 mnths | R3: 18+ mnths
B4: 7 | C4: 26 | E4: 1.5 - 3 | F4: 49 | H4: 0.5 - 1.5 | I4: 19 | K4: MIS | L4: =COUNTIF(Curr!W6:W178,Tables!J1) -> 54 | O4: Client Discovery | P4: =COUNTIF(Curr!G6:G178,Tables!$P$3) -> 17 | Q4: =COUNTIF(Curr!G6:G178,Tables!$Q$3) -> 26 | R4: =COUNTIF(Curr!G6:G178,Tables!$R$3) -> 21
B5: 7.1 | C5: 17 | E5: 10+ | F5: 22 | H5: 1.5 - 3 | I5: 56 | K5: Auto | L5: =COUNTIF(Curr!X6:X178,Tables!K1) -> 26 | O5: Renewal Planning | P5: =COUNTIF(Curr!H6:H178,Tables!$P$3) -> 12 | Q5: =COUNTIF(Curr!H6:H178,Tables!$Q$3) -> 33 | R5: =COUNTIF(Curr!H6:H178,Tables!$R$3) -> 77
B6: 7.2 | C6: 3 | E6: 3-5 | F6: 54 | H6: 3-5 | I6: 46 | K6: App / Sys Migration | L6: =COUNTIF(Curr!Y6:Y178,Tables!L1) -> 35 | O6: Subm Creation | P6: =COUNTIF(Curr!I6:I178,Tables!$P$3) -> 12 | Q6: =COUNTIF(Curr!I6:I178,Tables!$Q$3) -> 21 | R6: =COUNTIF(Curr!I6:I178,Tables!$R$3) -> 30
B7: 8 | C7: 37 | E7: 5-7 | F7: 19 | H7: 5-7 | I7: 15 | K7: Training / OJ Support | L7: =COUNTIF(Curr!Z6:Z178,Tables!M1) -> 145 | O7: Program Brokering | P7: =COUNTIF(Curr!J6:J178,Tables!$P$3) -> 9 | Q7: =COUNTIF(Curr!J6:J178,Tables!$Q$3) -> 3 | R7: =COUNTIF(Curr!J6:J178,Tables!$R$3) -> 7
B8: (blank) | C8: 1 | E8: 7-8 | F8: 9 | H8: 7-8 | I8: 10 | K8: Proc Exc (YB / GB / BB / MBB) | L8: =COUNTIF(Curr!AA6:AA178,Tables!N1) -> 25 | O8: Quote Review | P8: =COUNTIF(Curr!K6:K178,Tables!$P$3) -> 15 | Q8: =COUNTIF(Curr!K6:K178,Tables!$Q$3) -> 22 | R8: =COUNTIF(Curr!K6:K178,Tables!$R$3) -> 33
B9: 6 | C9: 7 | E9: 8-10 | F9: 6 | H9: 8-10 | I9: 9 | K9: Onshore Trans (no remote) | L9: =COUNTIF(Curr!AB6:AB178,Tables!O1) -> 22 | O9: Quote presentation | P9: =COUNTIF(Curr!L6:L178,Tables!$P$3) -> 9 | Q9: =COUNTIF(Curr!L6:L178,Tables!$Q$3) -> 15 | R9: =COUNTIF(Curr!L6:L178,Tables!$R$3) -> 20
B10: 8.2 | C10: 18 | E10: 0.5 - 1.5 | F10: 7 | H10: 10+ | I10: 8 | O10: Bind Auth & Review​ | P10: =COUNTIF(Curr!M6:M178,Tables!$P$3) -> 15 | Q10: =COUNTIF(Curr!M6:M178,Tables!$Q$3) -> 10 | R10: =COUNTIF(Curr!M6:M178,Tables!$R$3) -> 25
B11: 8.1 | C11: 57 | E11: 3 - 5 | F11: 1 | H11: 0.5 | I11: 2 | O11: Premium Financing | P11: =COUNTIF(Curr!N6:N178,Tables!$P$3) -> 15 | Q11: =COUNTIF(Curr!N6:N178,Tables!$Q$3) -> 10 | R11: =COUNTIF(Curr!N6:N178,Tables!$R$3) -> 10
B12: 5 | C12: 1 | E12: Total | F12: 167 | H12: 3 - 5 | I12: 1 | O12: Inv | P12: =COUNTIF(Curr!O6:O178,Tables!$P$3) -> 13 | Q12: =COUNTIF(Curr!O6:O178,Tables!$Q$3) -> 19 | R12: =COUNTIF(Curr!O6:O178,Tables!$R$3) -> 30
B13: Total | C13: 167 | H13: Total | I13: 166 | O13: Evidence of Coverage | P13: =COUNTIF(Curr!P6:P178,Tables!$P$3) -> 10 | Q13: =COUNTIF(Curr!P6:P178,Tables!$Q$3) -> 18 | R13: =COUNTIF(Curr!P6:P178,Tables!$R$3) -> 49
K14: Sys & App Experience | O14: Pol Admin | P14: =COUNTIF(Curr!Q6:Q178,Tables!$P$3) -> 15 | Q14: =COUNTIF(Curr!Q6:Q178,Tables!$Q$3) -> 16 | R14: =COUNTIF(Curr!Q6:Q178,Tables!$R$3) -> 43
B15: Geography Exposure | K15: Application | L15: No of Colleagues | M15: %age | O15: Endmnt | P15: =COUNTIF(Curr!R6:R178,Tables!$P$3) -> 14 | Q15: =COUNTIF(Curr!R6:R178,Tables!$Q$3) -> 27 | R15: =COUNTIF(Curr!R6:R178,Tables!$R$3) -> 67
B16: Location | C16: Count of P&C (yrs) | K16: EPIC | L16: =COUNTIF(Curr!AC6:AC178,Tables!P1) -> 116 | M16: =L16/GETPIVOTDATA("Employee Name",$B$3) -> 0.69461078 | O16: Claims Mgmt & Oversight | P16: =COUNTIF(Curr!S6:S178,Tables!$P$3) -> 8 | Q16: =COUNTIF(Curr!S6:S178,Tables!$Q$3) -> 13 | R16: =COUNTIF(Curr!S6:S178,Tables!$R$3) -> 22
B17: AUS | C17: 1 | K17: AMS 360 | L17: =COUNTIF(Curr!AD6:AD178,Tables!Q1) -> 50 | M17: =L17/GETPIVOTDATA("Employee Name",$B$3) -> 0.2994012 | O17: Claims Analytics | P17: =COUNTIF(Curr!T6:T178,Tables!$P$3) -> 5 | Q17: =COUNTIF(Curr!T6:T178,Tables!$Q$3) -> 10 | R17: =COUNTIF(Curr!T6:T178,Tables!$R$3) -> 17
B18: UK | C18: 8 | K18: CSR24 | L18: =COUNTIF(Curr!AE6:AE178,Tables!R1) -> 51 | M18: =L18/GETPIVOTDATA("Employee Name",$B$3) -> 0.30538922 | O18: Claims Creation Guide | P18: =COUNTIF(Curr!U6:U178,Tables!$P$3) -> 7 | Q18: =COUNTIF(Curr!U6:U178,Tables!$Q$3) -> 5 | R18: =COUNTIF(Curr!U6:U178,Tables!$R$3) -> 11
B19: UK & AUS | C19: 4 | K19: IMAGERIGHT | L19: =COUNTIF(Curr!AF6:AF178,Tables!S1) -> 58 | M19: =L19/GETPIVOTDATA("Employee Name",$B$3) -> 0.34730539
B20: USA | C20: 124
B21: (blank)
B22: USA;UK | C22: 12
B23: USA;Canada; | C23: 5
B24: APAC & UK | C24: 1
B25: USA / UK / AUS / CAN | C25: 1
B26: Other; | C26: 2
B27: APAC; | C27: 1
B28: USA;Canada;AUS; | C28: 1
B29: CAN | C29: 1
B30: USA;Other | C30: 1
B31: USA;Canada | C31: 1
B32: Other | C32: 1
B33: USA;UK;Canada | C33: 1
... B36: Total | C36: 167

Sheet Process training Matrix
A1: Sr No | B1: Stage | C1: Process | D1: Description | E1: Work-Types / Tasks | F1: Remarks (if any) | G1: SOP Status | H1: Type | I1: Training completed | J1: Training pending | K1: Abishek V | L1: Amrutha Arali | M1: Apoorva H A | N1: Binu K Bose | O1: Chetankumar Honakeri | P1: Geetanjali G | Q1: Harish Anand | R1: Joyline Viola Rebello | S1: Kumar, Mohan V | T1: Lakshmipathy Chalicheemala | U1: M Dhanashekar | V1: Mohamed Bilal Nazeer Ahamed | W1: Naresh Moguram | X1: Natri Aakash | Y1: Nidhi Kumari | Z1: Pooja S | AA1: Pradeep Kumar L | AB1: Prince Peter | AC1: Rohith R | AD1: Sajith C P | AE1: Shelina Jena | AF1: Sulthana, Zaiba | AG1: Suma P | AH1: Thirumala Reddy S | AI1: Veeranagaraj Hiremath | AJ1: Vikram Prakash Bhat | AK1: Sanjeev Krishna V | AL1: Vikram Anand | AM1: Santosh Chauhan | AN1: Jayesh Shetty | AO1: Sachin AK | AP1: Santhosh HS | AQ1: Meagan Lewis | AR1: Sandhya MS | AS1: Arun M U | AT1: Chethan HS | AU1: Harshitha K | AV1: Kiran Doddagoudar | AW1: Manasa BR | AX1: Prakash M | AY1: Ramya R C | AZ1: Ranjit Kumar Peddinti | BA1: Ranjitha R | BB1: Rehana S | BC1: Sangeetha AN | BD1: Vidyadhar Hiremath | BE1: Gaurav Sharma
A2: 1 | B2: Pre-Placement | C2: Client Discovery | D2: understanding the client’s business, risk profile, coverage needs, and objectives to inform program design and placement strategy​ | E2: Data Retrieval - Loss Run Management (Carrier Websites) | H2: SBU CSD | I2: =COUNTIF(K2:BE2,"P") -> 0 | J2: =COUNTIF(K2:BE2,"O") -> 44 | K2: O | L2: O | M2: O | N2: O | O2: O | P2: O | Q2: O | R2: O | S2: O | T2: O | U2: O | W2: O | X2: O | Y2: O | Z2: O | AA2: O | AB2: O | AC2: O | AD2: O | AE2: O | AF2: O | AG2: O | AH2: O | AI2: O | AJ2: O | AK2: O | AL2: O | AM2: O | AN2: O | AO2: O | AP2: O | AQ2: O | AR2: O | AS2: O | AT2: O | AU2: O | AV2: O | AW2: O | AX2: O | AY2: O | BA2: O | BB2: O | BC2: O | BD2: O
A3: 2 | E3: Data Retrieval - Loss Run Management (Carrier Websites) | H3: CR CSD | I3: =COUNTIF(K3:BE3,"P") -> 0 | J3: =COUNTIF(K3:BE3,"O") -> 44 | K3: O | L3: O | M3: O | N3: O | O3: O | P3: O | Q3: O | R3: O | S3: O | T3: O | U3: O | W3: O | X3: O | Y3: O | Z3: O | AA3: O | AB3: O | AC3: O | AD3: O | AE3: O | AF3: O | AG3: O | AH3: O | AI3: O | AJ3: O | AK3: O | AL3: O | AM3: O | AN3: O | AO3: O | AP3: O | AQ3: O | AR3: O | AS3: O | AT3: O | AU3: O | AV3: O | AW3: O | AX3: O | AY3: O | BA3: O | BB3: O | BC3: O | BD3: O
A4: 3 | E4: Data Loading / Analytics Support - SOV / Exposure Summary (Excel) | H4: SBU RSPIP | I4: =COUNTIF(K4:BE4,"P") -> 0 | J4: =COUNTIF(K4:BE4,"O") -> 44 | K4: O | L4: O | M4: O | N4: O | O4: O | P4: O | Q4: O | R4: O | S4: O | T4: O | U4: O | W4: O | X4: O | Y4: O | Z4: O | AA4: O | AB4: O | AC4: O | AD4: O | AE4: O | AF4: O | AG4: O | AH4: O | AI4: O | AJ4: O | AK4: O | AL4: O | AM4: O | AN4: O | AO4: O | AP4: O | AQ4: O | AR4: O | AS4: O | AT4: O | AU4: O | AV4: O | AW4: O | AX4: O | AY4: O | BA4: O | BB4: O | BC4: O | BD4: O
A5: 4 | E5: Data Loading / Analytics Support - SOV / Exposure Summary (Excel) | H5: CR AMS | I5: =COUNTIF(K5:BE5,"P") -> 0 | J5: =COUNTIF(K5:BE5,"O") -> 44 | K5: O | L5: O | M5: O | N5: O | O5: O | P5: O | Q5: O | R5: O | S5: O | T5: O | U5: O | W5: O | X5: O | Y5: O | Z5: O | AA5: O | AB5: O | AC5: O | AD5: O | AE5: O | AF5: O | AG5: O | AH5: O | AI5: O | AJ5: O | AK5: O | AL5: O | AM5: O | AN5: O | AO5: O | AP5: O | AQ5: O | AR5: O | AS5: O | AT5: O | AU5: O | AV5: O | AW5: O | AX5: O | AY5: O | BA5: O | BB5: O | BC5: O | BD5: O
A6: 5 | E6: Data Loading / Analytics Support - Summary of Insurance (Word / Epic) | H6: SBU CSD | I6: =COUNTIF(K6:BE6,"P") -> 0 | J6: =COUNTIF(K6:BE6,"O") -> 44 | K6: O | L6: O | M6: O | N6: O | O6: O | P6: O | Q6: O | R6: O | S6: O | T6: O | U6: O | W6: O | X6: O | Y6: O | Z6: O | AA6: O | AB6: O | AC6: O | AD6: O | AE6: O | AF6: O | AG6: O | AH6: O | AI6: O | AJ6: O | AK6: O | AL6: O | AM6: O | AN6: O | AO6: O | AP6: O | AQ6: O | AR6: O | AS6: O | AT6: O | AU6: O | AV6: O | AW6: O | AX6: O | AY6: O | BA6: O | BB6: O | BC6: O | BD6: O
A7: 6 | E7: Data Loading / Analytics Support - Summary of Insurance (Word / Epic) | H7: CR CSD | I7: =COUNTIF(K7:BE7,"P") -> 0 | J7: =COUNTIF(K7:BE7,"O") -> 44 | K7: O | L7: O | M7: O | N7: O | O7: O | P7: O | Q7: O | R7: O | S7: O | T7: O | U7: O | W7: O | X7: O | Y7: O | Z7: O | AA7: O | AB7: O | AC7: O | AD7: O | AE7: O | AF7: O | AG7: O | AH7: O | AI7: O | AJ7: O | AK7: O | AL7: O | AM7: O | AN7: O | AO7: O | AP7: O | AQ7: O | AR7: O | AS7: O | AT7: O | AU7: O | AV7: O | AW7: O | AX7: O | AY7: O | BA7: O | BB7: O | BC7: O | BD7: O
A8: 7 | E8: Data Loading / Analytics Support - Summary of Insurance (Excel) | H8: SBU RSPIP | I8: =COUNTIF(K8:BE8,"P") -> 0 | J8: =COUNTIF(K8:BE8,"O") -> 44 | K8: O | L8: O | M8: O | N8: O | O8: O | P8: O | Q8: O | R8: O | S8: O | T8: O | U8: O | W8: O | X8: O | Y8: O | Z8: O | AA8: O | AB8: O | AC8: O | AD8: O | AE8: O | AF8: O | AG8: O | AH8: O | AI8: O | AJ8: O | AK8: O | AL8: O | AM8: O | AN8: O | AO8: O | AP8: O | AQ8: O | AR8: O | AS8: O | AT8: O | AU8: O | AV8: O | AW8: O | AX8: O | AY8: O | BA8: O | BB8: O | BC8: O | BD8: O
A9: 8 | E9: Data Loading / Analytics Support - Summary of Insurance (Excel) | H9: CR AMS | I9: =COUNTIF(K9:BE9,"P") -> 0 | J9: =COUNTIF(K9:BE9,"O") -> 44 | K9: O | L9: O | M9: O | N9: O | O9: O | P9: O | Q9: O | R9: O | S9: O | T9: O | U9: O | W9: O | X9: O | Y9: O | Z9: O | AA9: O | AB9: O | AC9: O | AD9: O | AE9: O | AF9: O | AG9: O | AH9: O | AI9: O | AJ9: O | AK9: O | AL9: O | AM9: O | AN9: O | AO9: O | AP9: O | AQ9: O | AR9: O | AS9: O | AT9: O | AU9: O | AV9: O | AW9: O | AX9: O | AY9: O | BA9: O | BB9: O | BC9: O | BD9: O
A10: 9 | E10: Data Loading and Analytics support - Creating Loss Summary | H10: SBU CSD | I10: =COUNTIF(K10:BE10,"P") -> 0 | J10: =COUNTIF(K10:BE10,"O") -> 44 | K10: O | L10: O | M10: O | N10: O | O10: O | P10: O | Q10: O | R10: O | S10: O | T10: O | U10: O | W10: O | X10: O | Y10: O | Z10: O | AA10: O | AB10: O | AC10: O | AD10: O | AE10: O | AF10: O | AG10: O | AH10: O | AI10: O | AJ10: O | AK10: O | AL10: O | AM10: O | AN10: O | AO10: O | AP10: O | AQ10: O | AR10: O | AS10: O | AT10: O | AU10: O | AV10: O | AW10: O | AX10: O | AY10: O | BA10: O | BB10: O | BC10: O | BD10: O
A11: 10 | E11: Data Loading and Analytics support - Creating Loss Summary | H11: CR CSD | I11: =COUNTIF(K11:BE11,"P") -> 0 | J11: =COUNTIF(K11:BE11,"O") -> 44 | K11: O | L11: O | M11: O | N11: O | O11: O | P11: O | Q11: O | R11: O | S11: O | T11: O | U11: O | W11: O | X11: O | Y11: O | Z11: O | AA11: O | AB11: O | AC11: O | AD11: O | AE11: O | AF11: O | AG11: O | AH11: O | AI11: O | AJ11: O | AK11: O | AL11: O | AM11: O | AN11: O | AO11: O | AP11: O | AQ11: O | AR11: O | AS11: O | AT11: O | AU11: O | AV11: O | AW11: O | AX11: O | AY11: O | BA11: O | BB11: O | BC11: O | BD11: O
A12: 11 | C12: Renewal Planning | D12: Planning and coordination of renewal strategy, timelines, data requirements, and market approach to ensure policy renewal​ | E12: Policy Validation & Endorsement Reconciliation (Epic) | H12: SBU CSD | I12: =COUNTIF(K12:BE12,"P") -> 0 | J12: =COUNTIF(K12:BE12,"O") -> 44 | K12: O | L12: O | M12: O | N12: O | O12: O | P12: O | Q12: O | R12: O | S12: O | T12: O | U12: O | W12: O | X12: O | Y12: O | Z12: O | AA12: O | AB12: O | AC12: O | AD12: O | AE12: O | AF12: O | AG12: O | AH12: O | AI12: O | AJ12: O | AK12: O | AL12: O | AM12: O | AN12: O | AO12: O | AP12: O | AQ12: O | AR12: O | AS12: O | AT12: O | AU12: O | AV12: O | AW12: O | AX12: O | AY12: O | BA12: O | BB12: O | BC12: O | BD12: O
A13: 12 | D13: Planning and coordination of renewal strategy, timelines, data requirements, and market approach to ensure policy renewal​ | E13: Policy Validation & Endorsement Reconciliation (Epic) | H13: CR CSD | I13: =COUNTIF(K13:BE13,"P") -> 0 | J13: =COUNTIF(K13:BE13,"O") -> 44 | K13: O | L13: O | M13: O | N13: O | O13: O | P13: O | Q13: O | R13: O | S13: O | T13: O | U13: O | W13: O | X13: O | Y13: O | Z13: O | AA13: O | AB13: O | AC13: O | AD13: O | AE13: O | AF13: O | AG13: O | AH13: O | AI13: O | AJ13: O | AK13: O | AL13: O | AM13: O | AN13: O | AO13: O | AP13: O | AQ13: O | AR13: O | AS13: O | AT13: O | AU13: O | AV13: O | AW13: O | AX13: O | AY13: O | BA13: O | BB13: O | BC13: O | BD13: O
A14: 13 | C14: Submission Creation | D14: Preparation of underwriting submissions, including exposure data, loss history, and supporting documentation, for delivery to insurance markets​ | E14: Policy Setup / Creation / Submission in Epic | H14: SBU CSD | I14: =COUNTIF(K14:BE14,"P") -> 40 | J14: =COUNTIF(K14:BE14,"O") -> 4 | K14: P | L14: P | M14: P | N14: P | O14: P | P14: P | Q14: P | R14: P | S14: P | T14: P | U14: P | W14: P | X14: P | Y14: P | Z14: P | AA14: P | AB14: P | AC14: P | AD14: P | AE14: P | AF14: P | AG14: P | AH14: P | AI14: P | AJ14: P | AK14: P | AL14: P | AM14: P | AN14: P | AO14: O | AP14: O | AQ14: O | AR14: O | AS14: P | AT14: P | AU14: P | AV14: P | AW14: P | AX14: P | AY14: P | BA14: P | BB14: P | BC14: P | BD14: P
A15: 14 | E15: Policy Setup / Creation / Submission in Epic | H15: CR CSD | I15: =COUNTIF(K15:BE15,"P") -> 40 | J15: =COUNTIF(K15:BE15,"O") -> 4 | K15: P | L15: P | M15: P | N15: P | O15: P | P15: P | Q15: P | R15: P | S15: P | T15: P | U15: P | W15: P | X15: P | Y15: P | Z15: P | AA15: P | AB15: P | AC15: P | AD15: P | AE15: P | AF15: P | AG15: P | AH15: P | AI15: P | AJ15: P | AK15: P | AL15: P | AM15: P | AN15: P | AO15: O | AP15: O | AQ15: O | AR15: O | AS15: P | AT15: P | AU15: P | AV15: P | AW15: P | AX15: P | AY15: P | BA15: P | BB15: P | BC15: P | BD15: P
A16: 15 | E16: Pre-filling supplemental applications with prior / existing client or app data​ | H16: SBU RSPIP | I16: =COUNTIF(K16:BE16,"P") -> 0 | J16: =COUNTIF(K16:BE16,"O") -> 44 | K16: O | L16: O | M16: O | N16: O | O16: O | P16: O | Q16: O | R16: O | S16: O | T16: O | U16: O | W16: O | X16: O | Y16: O | Z16: O | AA16: O | AB16: O | AC16: O | AD16: O | AE16: O | AF16: O | AG16: O | AH16: O | AI16: O | AJ16: O | AK16: O | AL16: O | AM16: O | AN16: O | AO16: O | AP16: O | AQ16: O | AR16: O | AS16: O | AT16: O | AU16: O | AV16: O | AW16: O | AX16: O | AY16: O | BA16: O | BB16: O | BC16: O | BD16: O
A17: 16 | E17: Pre-filling supplemental applications with prior / existing client or app data​ | H17: CR AMS | I17: =COUNTIF(K17:BE17,"P") -> 0 | J17: =COUNTIF(K17:BE17,"O") -> 44 | K17: O | L17: O | M17: O | N17: O | O17: O | P17: O | Q17: O | R17: O | S17: O | T17: O | U17: O | W17: O | X17: O | Y17: O | Z17: O | AA17: O | AB17: O | AC17: O | AD17: O | AE17: O | AF17: O | AG17: O | AH17: O | AI17: O | AJ17: O | AK17: O | AL17: O | AM17: O | AN17: O | AO17: O | AP17: O | AQ17: O | AR17: O | AS17: O | AT17: O | AU17: O | AV17: O | AW17: O | AX17: O | AY17: O | BA17: O | BB17: O | BC17: O | BD17: O
A18: 17 | B18: Placement | C18: Program Brokering​ | D18: Marketing of the client’s insurance program to carriers, negotiation of terms and pricing, and coordination of carrier responses to secure optimal coverage​ | E18: Online Quoting | H18: SBU CSD | I18: =COUNTIF(K18:BE18,"P") -> 0 | J18: =COUNTIF(K18:BE18,"O") -> 44 | K18: O | L18: O | M18: O | N18: O | O18: O | P18: O | Q18: O | R18: O | S18: O | T18: O | U18: O | W18: O | X18: O | Y18: O | Z18: O | AA18: O | AB18: O | AC18: O | AD18: O | AE18: O | AF18: O | AG18: O | AH18: O | AI18: O | AJ18: O | AK18: O | AL18: O | AM18: O | AN18: O | AO18: O | AP18: O | AQ18: O | AR18: O | AS18: O | AT18: O | AU18: O | AV18: O | AW18: O | AX18: O | AY18: O | BA18: O | BB18: O | BC18: O | BD18: O
A19: 18 | E19: Online Quoting | H19: CR CSD | I19: =COUNTIF(K19:BE19,"P") -> 0 | J19: =COUNTIF(K19:BE19,"O") -> 44 | K19: O | L19: O | M19: O | N19: O | O19: O | P19: O | Q19: O | R19: O | S19: O | T19: O | U19: O | W19: O | X19: O | Y19: O | Z19: O | AA19: O | AB19: O | AC19: O | AD19: O | AE19: O | AF19: O | AG19: O | AH19: O | AI19: O | AJ19: O | AK19: O | AL19: O | AM19: O | AN19: O | AO19: O | AP19: O | AQ19: O | AR19: O | AS19: O | AT19: O | AU19: O | AV19: O | AW19: O | AX19: O | AY19: O | BA19: O | BB19: O | BC19: O | BD19: O
A20: 19 | C20: Quote Review​ | D20: Comparison of carrier quotes including key policy details (e.g., changes from expiring, form inclusions, edition dates), to identify suitable options for client consideration​ | E20: Coverage Comparison – Expiring vs Renewal | H20: SBU RSPIP | I20: =COUNTIF(K20:BE20,"P") -> 0 | J20: =COUNTIF(K20:BE20,"O") -> 44 | K20: O | L20: O | M20: O | N20: O | O20: O | P20: O | Q20: O | R20: O | S20: O | T20: O | U20: O | W20: O | X20: O | Y20: O | Z20: O | AA20: O | AB20: O | AC20: O | AD20: O | AE20: O | AF20: O | AG20: O | AH20: O | AI20: O | AJ20: O | AK20: O | AL20: O | AM20: O | AN20: O | AO20: O | AP20: O | AQ20: O | AR20: O | AS20: O | AT20: O | AU20: O | AV20: O | AW20: O | AX20: O | AY20: O | BA20: O | BB20: O | BC20: O | BD20: O
A21: 20 | E21: Coverage Comparison – Expiring vs Renewal | H21: CR AMS | I21: =COUNTIF(K21:BE21,"P") -> 0 | J21: =COUNTIF(K21:BE21,"O") -> 44 | K21: O | L21: O | M21: O | N21: O | O21: O | P21: O | Q21: O | R21: O | S21: O | T21: O | U21: O | W21: O | X21: O | Y21: O | Z21: O | AA21: O | AB21: O | AC21: O | AD21: O | AE21: O | AF21: O | AG21: O | AH21: O | AI21: O | AJ21: O | AK21: O | AL21: O | AM21: O | AN21: O | AO21: O | AP21: O | AQ21: O | AR21: O | AS21: O | AT21: O | AU21: O | AV21: O | AW21: O | AX21: O | AY21: O | BA21: O | BB21: O | BC21: O | BD21: O
A22: 21 | C22: Quote Presentation​ | D22: Compilation and presentation of carrier quotes, including coverage comparisons, pricing, and key terms, to support client decision-making​ | E22: Proposal Preparation | H22: SBU RSPIP | I22: =COUNTIF(K22:BE22,"P") -> 0 | J22: =COUNTIF(K22:BE22,"O") -> 44 | K22: O | L22: O | M22: O | N22: O | O22: O | P22: O | Q22: O | R22: O | S22: O | T22: O | U22: O | W22: O | X22: O | Y22: O | Z22: O | AA22: O | AB22: O | AC22: O | AD22: O | AE22: O | AF22: O | AG22: O | AH22: O | AI22: O | AJ22: O | AK22: O | AL22: O | AM22: O | AN22: O | AO22: O | AP22: O | AQ22: O | AR22: O | AS22: O | AT22: O | AU22: O | AV22: O | AW22: O | AX22: O | AY22: O | BA22: O | BB22: O | BC22: O | BD22: O
A23: 22 | E23: Proposal Preparation | H23: CR AMS | I23: =COUNTIF(K23:BE23,"P") -> 0 | J23: =COUNTIF(K23:BE23,"O") -> 44 | K23: O | L23: O | M23: O | N23: O | O23: O | P23: O | Q23: O | R23: O | S23: O | T23: O | U23: O | W23: O | X23: O | Y23: O | Z23: O | AA23: O | AB23: O | AC23: O | AD23: O | AE23: O | AF23: O | AG23: O | AH23: O | AI23: O | AJ23: O | AK23: O | AL23: O | AM23: O | AN23: O | AO23: O | AP23: O | AQ23: O | AR23: O | AS23: O | AT23: O | AU23: O | AV23: O | AW23: O | AX23: O | AY23: O | BA23: O | BB23: O | BC23: O | BD23: O
A24: 23 | C24: Bind Authorization & Review​ | D24: Confirmation of client binding instructions, review of final terms and conditions, and authorization to bind coverage with selected carrier(s)​ | E24: Epic Client Setup | F24: This work type was a part of the EPIC workshop. The pilot team members along with the first cohort of 24 (total 27) have a good understanding of the work type (Standard process for both SBU & MM) | G24: Skeleton version prepared | H24: SBU CSD | I24: =COUNTIF(K24:BE24,"P") -> 44 | J24: =COUNTIF(K24:BE24,"O") -> 0 | K24: P | L24: P | M24: P | N24: P | O24: P | P24: P | Q24: P | R24: P | S24: P | T24: P | U24: P | W24: P | X24: P | Y24: P | Z24: P | AA24: P | AB24: P | AC24: P | AD24: P | AE24: P | AF24: P | AG24: P | AH24: P | AI24: P | AJ24: P | AK24: P | AL24: P | AM24: P | AN24: P | AO24: P | AP24: P | AQ24: P | AR24: P | AS24: P | AT24: P | AU24: P | AV24: P | AW24: P | AX24: P | AY24: P | BA24: P | BB24: P | BC24: P | BD24: P
A25: 24 | E25: Epic Client Setup | H25: CR CSD | I25: =COUNTIF(K25:BE25,"P") -> 44 | J25: =COUNTIF(K25:BE25,"O") -> 0 | K25: P | L25: P | M25: P | N25: P | O25: P | P25: P | Q25: P | R25: P | S25: P | T25: P | U25: P | W25: P | X25: P | Y25: P | Z25: P | AA25: P | AB25: P | AC25: P | AD25: P | AE25: P | AF25: P | AG25: P | AH25: P | AI25: P | AJ25: P | AK25: P | AL25: P | AM25: P | AN25: P | AO25: P | AP25: P | AQ25: P | AR25: P | AS25: P | AT25: P | AU25: P | AV25: P | AW25: P | AX25: P | AY25: P | BA25: P | BB25: P | BC25: P | BD25: P
A26: 25 | C26: Premium Financing​ | D26: Coordination of premium financing options as requested by the client​ | E26: Premium finance agreements (PFAs)​ | I26: =COUNTIF(K26:BE26,"P") -> 0 | J26: =COUNTIF(K26:BE26,"O") -> 44 | K26: O | L26: O | M26: O | N26: O | O26: O | P26: O | Q26: O | R26: O | S26: O | T26: O | U26: O | W26: O | X26: O | Y26: O | Z26: O | AA26: O | AB26: O | AC26: O | AD26: O | AE26: O | AF26: O | AG26: O | AH26: O | AI26: O | AJ26: O | AK26: O | AL26: O | AM26: O | AN26: O | AO26: O | AP26: O | AQ26: O | AR26: O | AS26: O | AT26: O | AU26: O | AV26: O | AW26: O | AX26: O | AY26: O | BA26: O | BB26: O | BC26: O | BD26: O
A27: 26 | E27: Premium finance agreements (PFAs)​ | I27: =COUNTIF(K27:BE27,"P") -> 0 | J27: =COUNTIF(K27:BE27,"O") -> 44 | K27: O | L27: O | M27: O | N27: O | O27: O | P27: O | Q27: O | R27: O | S27: O | T27: O | U27: O | W27: O | X27: O | Y27: O | Z27: O | AA27: O | AB27: O | AC27: O | AD27: O | AE27: O | AF27: O | AG27: O | AH27: O | AI27: O | AJ27: O | AK27: O | AL27: O | AM27: O | AN27: O | AO27: O | AP27: O | AQ27: O | AR27: O | AS27: O | AT27: O | AU27: O | AV27: O | AW27: O | AX27: O | AY27: O | BA27: O | BB27: O | BC27: O | BD27: O
A28: 27 | C28: Invoicing​ | D28: Preparation and issuance of client invoices reflecting premiums, fees, taxes, and payment terms following policy binding​ | E28: Invoice Creation | F28: 3 Pilot team members have been trained - few variations in the process, will need further coaching | G28: Work in progress | H28: SBU CSD | I28: =COUNTIF(K28:BE28,"P") -> 33 | J28: =COUNTIF(K28:BE28,"O") -> 11 | K28: P | L28: P | M28: P | N28: P | O28: P | P28: P | Q28: P | R28: P | S28: P | T28: P | U28: P | W28: P | X28: P | Y28: P | Z28: P | AA28: P | AB28: P | AC28: P | AD28: P | AE28: P | AF28: P | AG28: P | AH28: P | AI28: P | AJ28: P | AK28: P | AL28: P | AM28: P | AN28: P | AO28: P | AP28: P | AQ28: P | AR28: P | AS28: O | AT28: O | AU28: O | AV28: O | AW28: O | AX28: O | AY28: O | BA28: O | BB28: O | BC28: O | BD28: O
A29: 28 | E29: Invoice Creation | F29: (Standard process for both SBU & MM) | H29: CR CSD | I29: =COUNTIF(K29:BE29,"P") -> 33 | J29: =COUNTIF(K29:BE29,"O") -> 11 | K29: P | L29: P | M29: P | N29: P | O29: P | P29: P | Q29: P | R29: P | S29: P | T29: P | U29: P | W29: P | X29: P | Y29: P | Z29: P | AA29: P | AB29: P | AC29: P | AD29: P | AE29: P | AF29: P | AG29: P | AH29: P | AI29: P | AJ29: P | AK29: P | AL29: P | AM29: P | AN29: P | AO29: P | AP29: P | AQ29: P | AR29: P | AS29: O | AT29: O | AU29: O | AV29: O | AW29: O | AX29: O | AY29: O | BA29: O | BB29: O | BC29: O | BD29: O
A30: 29 | E30: Surplus Lines Compliance Preparation | H30: SBU RSPIP | I30: =COUNTIF(K30:BE30,"P") -> 0 | J30: =COUNTIF(K30:BE30,"O") -> 44 | K30: O | L30: O | M30: O | N30: O | O30: O | P30: O | Q30: O | R30: O | S30: O | T30: O | U30: O | W30: O | X30: O | Y30: O | Z30: O | AA30: O | AB30: O | AC30: O | AD30: O | AE30: O | AF30: O | AG30: O | AH30: O | AI30: O | AJ30: O | AK30: O | AL30: O | AM30: O | AN30: O | AO30: O | AP30: O | AQ30: O | AR30: O | AS30: O | AT30: O | AU30: O | AV30: O | AW30: O | AX30: O | AY30: O | BA30: O | BB30: O | BC30: O | BD30: O
A31: 30 | E31: Surplus Lines Compliance Preparation | H31: CR AMS | I31: =COUNTIF(K31:BE31,"P") -> 0 | J31: =COUNTIF(K31:BE31,"O") -> 44 | K31: O | L31: O | M31: O | N31: O | O31: O | P31: O | Q31: O | R31: O | S31: O | T31: O | U31: O | W31: O | X31: O | Y31: O | Z31: O | AA31: O | AB31: O | AC31: O | AD31: O | AE31: O | AF31: O | AG31: O | AH31: O | AI31: O | AJ31: O | AK31: O | AL31: O | AM31: O | AN31: O | AO31: O | AP31: O | AQ31: O | AR31: O | AS31: O | AT31: O | AU31: O | AV31: O | AW31: O | AX31: O | AY31: O | BA31: O | BB31: O | BC31: O | BD31: O
A32: 31 | B32: Post Placement | C32: Evidence Of Coverage | D32: Issuance and management of certificates and other evidence of insurance documents to verify coverage for clients and third parties​ | E32: Mid-term Certificate of Insurance | F32: 3 pilot team members + 3 more have been trained and all are well equipped to handle processing independently - The training has been completed for SBU ONLY (processed on EPIC). MM process training (on CSR 24) is yet to happen | G32: SOP for SBU - skeleton version ready | H32: SBU CSD | I32: =COUNTIF(K32:BE32,"P") -> 6 | J32: =COUNTIF(K32:BE32,"O") -> 38 | K32: O | L32: O | M32: O | N32: O | O32: P | P32: O | Q32: O | R32: O | S32: P | T32: O | U32: O | W32: O | X32: O | Y32: O | Z32: O | AA32: O | AB32: O | AC32: O | AD32: O | AE32: O | AF32: O | AG32: O | AH32: P | AI32: O | AJ32: O | AK32: O | AL32: P | AM32: P | AN32: P | AO32: O | AP32: O | AQ32: O | AR32: O | AS32: O | AT32: O | AU32: O | AV32: O | AW32: O | AX32: O | AY32: O | BA32: O | BB32: O | BC32: O | BD32: O
A33: 32 | E33: Mid-term Certificate of Insurance | H33: CR CSD | I33: =COUNTIF(K33:BE33,"P") -> 6 | J33: =COUNTIF(K33:BE33,"O") -> 38 | K33: O | L33: O | M33: O | N33: O | O33: P | P33: O | Q33: O | R33: O | S33: P | T33: O | U33: O | W33: O | X33: O | Y33: O | Z33: O | AA33: O | AB33: O | AC33: O | AD33: O | AE33: O | AF33: O | AG33: O | AH33: P | AI33: O | AJ33: O | AK33: O | AL33: P | AM33: P | AN33: P | AO33: O | AP33: O | AQ33: O | AR33: O | AS33: O | AT33: O | AU33: O | AV33: O | AW33: O | AX33: O | AY33: O | BA33: O | BB33: O | BC33: O | BD33: O
A34: 33 | E34: Renewal Certificates of Insurance | F34: 3 pilot team members + 3 have been trained on Renewal issuance (for SBU), however preparing holder list etc. is yet to be covered (CSR 24 used for MM is pending too) | G34: SOP for SBU - skeleton version ready | H34: SBU CSD | I34: =COUNTIF(K34:BE34,"P") -> 3 | J34: =COUNTIF(K34:BE34,"O") -> 41 | K34: O | L34: O | M34: O | N34: O | O34: O | P34: O | Q34: O | R34: O | S34: O | T34: O | U34: O | W34: O | X34: O | Y34: O | Z34: O | AA34: O | AB34: O | AC34: O | AD34: O | AE34: O | AF34: O | AG34: O | AH34: O | AI34: O | AJ34: O | AK34: O | AL34: P | AM34: P | AN34: P | AO34: O | AP34: O | AQ34: O | AR34: O | AS34: O | AT34: O | AU34: O | AV34: O | AW34: O | AX34: O | AY34: O | BA34: O | BB34: O | BC34: O | BD34: O
A35: 34 | E35: Renewal Certificates of Insurance | H35: CR CSD | I35: =COUNTIF(K35:BE35,"P") -> 3 | J35: =COUNTIF(K35:BE35,"O") -> 41 | K35: O | L35: O | M35: O | N35: O | O35: O | P35: O | Q35: O | R35: O | S35: O | T35: O | U35: O | W35: O | X35: O | Y35: O | Z35: O | AA35: O | AB35: O | AC35: O | AD35: O | AE35: O | AF35: O | AG35: O | AH35: O | AI35: O | AJ35: O | AK35: O | AL35: P | AM35: P | AN35: P | AO35: O | AP35: O | AQ35: O | AR35: O | AS35: O | AT35: O | AU35: O | AV35: O | AW35: O | AX35: O | AY35: O | BA35: O | BB35: O | BC35: O | BD35: O
A36: 35 | E36: Evidence of Property | F36: To be considered starting Thursday (9th Jul'26) post walkthrough | H36: SBU CSD | I36: =COUNTIF(K36:BE36,"P") -> 0 | J36: =COUNTIF(K36:BE36,"O") -> 44 | K36: O | L36: O | M36: O | N36: O | O36: O | P36: O | Q36: O | R36: O | S36: O | T36: O | U36: O | W36: O | X36: O | Y36: O | Z36: O | AA36: O | AB36: O | AC36: O | AD36: O | AE36: O | AF36: O | AG36: O | AH36: O | AI36: O | AJ36: O | AK36: O | AL36: O | AM36: O | AN36: O | AO36: O | AP36: O | AQ36: O | AR36: O | AS36: O | AT36: O | AU36: O | AV36: O | AW36: O | AX36: O | AY36: O | BA36: O | BB36: O | BC36: O | BD36: O
A37: 36 | E37: Evidence of Property | H37: CR CSD | I37: =COUNTIF(K37:BE37,"P") -> 0 | J37: =COUNTIF(K37:BE37,"O") -> 44 | K37: O | L37: O | M37: O | N37: O | O37: O | P37: O | Q37: O | R37: O | S37: O | T37: O | U37: O | W37: O | X37: O | Y37: O | Z37: O | AA37: O | AB37: O | AC37: O | AD37: O | AE37: O | AF37: O | AG37: O | AH37: O | AI37: O | AJ37: O | AK37: O | AL37: O | AM37: O | AN37: O | AO37: O | AP37: O | AQ37: O | AR37: O | AS37: O | AT37: O | AU37: O | AV37: O | AW37: O | AX37: O | AY37: O | BA37: O | BB37: O | BC37: O | BD37: O
A38: 37 | E38: Auto ID Cards | F38: To be considered starting Thursday (9th Jul'26) post walkthrough | H38: SBU CSD | I38: =COUNTIF(K38:BE38,"P") -> 0 | J38: =COUNTIF(K38:BE38,"O") -> 44 | K38: O | L38: O | M38: O | N38: O | O38: O | P38: O | Q38: O | R38: O | S38: O | T38: O | U38: O | W38: O | X38: O | Y38: O | Z38: O | AA38: O | AB38: O | AC38: O | AD38: O | AE38: O | AF38: O | AG38: O | AH38: O | AI38: O | AJ38: O | AK38: O | AL38: O | AM38: O | AN38: O | AO38: O | AP38: O | AQ38: O | AR38: O | AS38: O | AT38: O | AU38: O | AV38: O | AW38: O | AX38: O | AY38: O | BA38: O | BB38: O | BC38: O | BD38: O
A39: 38 | E39: Auto ID Cards | H39: CR CSD | I39: =COUNTIF(K39:BE39,"P") -> 0 | J39: =COUNTIF(K39:BE39,"O") -> 44 | K39: O | L39: O | M39: O | N39: O | O39: O | P39: O | Q39: O | R39: O | S39: O | T39: O | U39: O | W39: O | X39: O | Y39: O | Z39: O | AA39: O | AB39: O | AC39: O | AD39: O | AE39: O | AF39: O | AG39: O | AH39: O | AI39: O | AJ39: O | AK39: O | AL39: O | AM39: O | AN39: O | AO39: O | AP39: O | AQ39: O | AR39: O | AS39: O | AT39: O | AU39: O | AV39: O | AW39: O | AX39: O | AY39: O | BA39: O | BB39: O | BC39: O | BD39: O
A40: 39 | E40: Renewal Auto ID Cards | F40: To be considered starting Thursday (9th Jul'26) post walkthrough | H40: SBU CSD | I40: =COUNTIF(K40:BE40,"P") -> 0 | J40: =COUNTIF(K40:BE40,"O") -> 44 | K40: O | L40: O | M40: O | N40: O | O40: O | P40: O | Q40: O | R40: O | S40: O | T40: O | U40: O | W40: O | X40: O | Y40: O | Z40: O | AA40: O | AB40: O | AC40: O | AD40: O | AE40: O | AF40: O | AG40: O | AH40: O | AI40: O | AJ40: O | AK40: O | AL40: O | AM40: O | AN40: O | AO40: O | AP40: O | AQ40: O | AR40: O | AS40: O | AT40: O | AU40: O | AV40: O | AW40: O | AX40: O | AY40: O | BA40: O | BB40: O | BC40: O | BD40: O
...
